try:
    print(x)
except:
    print("an exception occured")
finally:
    print("The 'try except' is finsihed")
